<?xml version="1.0" ?>
<!-- =================================================================================== -->
<!-- |    This document was autogenerated by xacro from robot.xacro                    | -->
<!-- |    EDITING THIS FILE BY HAND IS NOT RECOMMENDED                                 | -->
<!-- =================================================================================== -->
<robot name="robot">
  <material name="black">
    <color rgba="0.0 0.0 0.0 1.0"/>
  </material>
  <material name="blue">
    <color rgba="0.0 0.0 0.8 1.0"/>
  </material>
  <material name="green">
    <color rgba="0.0 0.8 0.0 1.0"/>
  </material>
  <material name="grey">
    <color rgba="0.2 0.2 0.2 1.0"/>
  </material>
  <material name="silver">
    <color rgba="0.9137254901960784 0.9137254901960784 0.8470588235294118 1.0"/>
  </material>
  <material name="orange">
    <color rgba="1.0 0.4235294117647059 0.0392156862745098 1.0"/>
  </material>
  <material name="brown">
    <color rgba="0.8705882352941177 0.8117647058823529 0.7647058823529411 1.0"/>
  </material>
  <material name="red">
    <color rgba="0.8 0.0 0.0 1.0"/>
  </material>
  <material name="white">
    <color rgba="1.0 1.0 1.0 1.0"/>
  </material>
  <!-- ros_control plugin -->
  <gazebo>
    <plugin filename="liblegged_hw_sim.so" name="gazebo_ros_control">
      <robotNamespace>/</robotNamespace>
      <robotParam>legged_robot_description</robotParam>
      <robotSimType>legged_gazebo/LeggedHWSim</robotSimType>
    </plugin>
  </gazebo>
  <gazebo>
    <plugin filename="libgazebo_ros_p3d.so" name="p3d_base_controller">
      <alwaysOn>true</alwaysOn>
      <updateRate>1000.0</updateRate>
      <bodyName>base</bodyName>
      <topicName>ground_truth/state</topicName>
      <gaussianNoise>0</gaussianNoise>
      <frameName>world</frameName>
      <xyzOffsets>0 0 0</xyzOffsets>
      <rpyOffsets>0 0 0</rpyOffsets>
    </plugin>
  </gazebo>
  <link name="base">
    <visual>
      <origin rpy="0 0 0" xyz="0 0 0"/>
      <geometry>
        <mesh filename="package://legged_unitree_description/meshes/a1/Body.dae" scale="1 1 1"/>
      </geometry>
    </visual>
    <collision>
      <origin rpy="0 0 0" xyz="0 0 0"/>
      <geometry>
        <box size="0.267 0.194 0.114"/>
      </geometry>
    </collision>
    <inertial>
      <origin rpy="0 0 0" xyz="0.0 0.0 0.15"/>
      <mass value="6.5"/>
      <inertia ixx="0.3006167" ixy="-0.0" ixz="-0.0" iyy="0.23837" iyz="-0.0" izz="0.09690467"/>
    </inertial>
  </link>
  <!-- Imu is fixed to the base link -->
  <joint name="unitree_imu_joint" type="fixed">
    <origin rpy="0. 0. 0." xyz="0. 0. 0."/>
    <parent link="base"/>
    <child link="unitree_imu"/>
  </joint>
  <!-- Imu link -->
  <link name="unitree_imu">
    <inertial>
      <mass value="0.01"/>
      <origin rpy="0 0 0" xyz="0 0 0"/>
      <inertia ixx="0.000001" ixy="0" ixz="0" iyy="0.000001" iyz="0" izz="0.000001"/>
    </inertial>
    <visual>
      <origin rpy="0 0 0" xyz="0 0 0"/>
      <geometry>
        <box size="0.015 0.015 0.004"/>
      </geometry>
    </visual>
    <material name="orange">
      <color rgba="255 108 10 255"/>
    </material>
  </link>
  <gazebo reference="unitree_imu">
    <material>Gazebo/Orange</material>
  </gazebo>
  <gazebo reference="unitree_imu_joint">
    <disableFixedJointLumping>true</disableFixedJointLumping>
  </gazebo>
  <joint name="L_JHipRz" type="revolute">
    <origin rpy="0 0 0" xyz="0 0.075 0"/>
    <parent link="base"/>
    <child link="L_LHipRz"/>
    <axis xyz="0 0 1"/>
    <dynamics damping="0" friction="0"/>
    <limit effort="33.5" lower="-0.8028514559173915" upper="0.8028514559173915" velocity="21"/>
  </joint>
  <link name="L_LHipRz">
    <visual>
      <origin rpy="0 0 0.0" xyz="0 0 0"/>
      <geometry>
        <mesh filename="package://legged_unitree_description/meshes/a1/L_HipRz.dae" scale="1 1 1"/>
      </geometry>
      <material name="orange"/>
    </visual>
    <inertial>
      <origin rpy="0 0 0" xyz="0.0 0.0 -0.01"/>
      <mass value="0.30"/>
      <inertia ixx="0.003735" ixy="0.0" ixz="0.0" iyy="0.01391" iyz="0.0" izz="0.01355"/>
    </inertial>
  </link>
  <joint name="L_JHipRx" type="revolute">
    <origin rpy="0 0 0" xyz="-0.041 0.0 -0.0885"/>
    <parent link="L_LHipRz"/>
    <child link="L_LHipRx"/>
    <axis xyz="1 0 0"/>
    <dynamics damping="0" friction="0"/>
    <limit effort="33.5" lower="-0.8028514559173915" upper="-0.8028514559173915" velocity="33.5"/>
  </joint>
  <link name="L_LHipRx">
    <visual>
      <origin rpy="0 -1.57 0.0" xyz="0 0 0"/>
      <geometry>
        <mesh filename="package://legged_unitree_description/meshes/a1/L_HipRx.dae" scale="1 1 1"/>
      </geometry>
      <material name="orange"/>
    </visual>
    <inertial>
      <origin rpy="0 0 0" xyz="0.0 0.0 -0.01"/>
      <mass value="0.30"/>
      <inertia ixx="0.003735" ixy="0.0" ixz="0.0" iyy="0.01391" iyz="0.0" izz="0.01355"/>
    </inertial>
  </link>
  <joint name="L_JThigh" type="revolute">
    <origin rpy="0 0 0" xyz="0.065 0.0 0.0"/>
    <parent link="L_LHipRx"/>
    <child link="L_LThigh"/>
    <axis xyz="0 1 0"/>
    <dynamics damping="0" friction="0"/>
    <limit effort="33.5" lower="-0.8028514559173915" upper="-0.8028514559173915" velocity="33.5"/>
  </joint>
  <link name="L_LThigh">
    <visual>
      <origin rpy="0 1.57 -1.57" xyz="0 0 0"/>
      <geometry>
        <mesh filename="package://legged_unitree_description/meshes/a1/L_Thigh.dae" scale="1 1 1"/>
      </geometry>
      <material name="orange"/>
    </visual>
    <inertial>
      <origin rpy="0 0 0" xyz="0.0 0.0 -0.01"/>
      <mass value="1.0"/>
      <inertia ixx="0.003735" ixy="0.0" ixz="0.0" iyy="0.01391" iyz="0.0" izz="0.01355"/>
    </inertial>
  </link>
  <joint name="L_JKnee" type="revolute">
    <origin rpy="0 0 0" xyz="0.0 -0.017875 -0.247"/>
    <parent link="L_LThigh"/>
    <child link="L_LShank"/>
    <axis xyz="0 1 0"/>
    <dynamics damping="0" friction="0"/>
    <limit effort="33.5" lower="-0.8028514559173915" upper="-0.8028514559173915" velocity="33.5"/>
  </joint>
  <link name="L_LShank">
    <visual>
      <origin rpy="1.57 1.57 0" xyz="0 0 0"/>
      <geometry>
        <mesh filename="package://legged_unitree_description/meshes/a1/L_LowerLeg3_drawing.dae" scale="1 1 1"/>
      </geometry>
      <material name="orange"/>
    </visual>
    <inertial>
      <origin rpy="0 0 0" xyz="-0.03416 -0.00075 -0.01"/>
      <mass value="0.70"/>
      <inertia ixx="0.003735" ixy="0.0" ixz="0.0" iyy="0.01391" iyz="0.0" izz="0.01355"/>
    </inertial>
  </link>
  <joint name="L_JAnkle" type="revolute">
    <origin rpy="0 0 0" xyz="0.0 0.0 -0.247"/>
    <parent link="L_LShank"/>
    <child link="L_Foot"/>
    <axis xyz="0 1 0"/>
    <dynamics damping="0" friction="0"/>
    <limit effort="33.5" lower="-0.8028514559173915" upper="-0.8028514559173915" velocity="33.5"/>
  </joint>
  <link name="L_Foot">
    <visual>
      <origin rpy="1.57 1.57 0" xyz="0 0 0"/>
      <geometry>
        <mesh filename="package://legged_unitree_description/meshes/a1/L_foot_drawing.dae" scale="1 1 1"/>
      </geometry>
      <material name="orange"/>
    </visual>
    <visual>
      <geometry>
        <sphere radius="0.001"/>
      </geometry>
      <origin rpy="0 0 0" xyz="0.125 0.0 -0.033"/>
    </visual>
    <collision>
      <geometry>
        <sphere radius="0.0"/>
      </geometry>
      <origin rpy="0 0 0" xyz="0.125 0.0 -0.033"/>
    </collision>
    <visual>
      <geometry>
        <sphere radius="0.001"/>
      </geometry>
      <origin rpy="0 0 0" xyz="-0.025 0.0 -0.033"/>
    </visual>
    <collision>
      <geometry>
        <sphere radius="0.0"/>
      </geometry>
      <origin rpy="0 0 0" xyz="-0.025 0.0 -0.033"/>
    </collision>
    <inertial>
      <origin rpy="0 0 0" xyz="0.0 0.0 -0.01"/>
      <mass value="0.30"/>
      <inertia ixx="0.003735" ixy="0.0" ixz="0.0" iyy="0.01391" iyz="0.0" izz="0.01355"/>
    </inertial>
  </link>
  <gazebo reference="L_LHipRz">
    <mu1>0.2</mu1>
    <mu2>0.2</mu2>
    <material>Gazebo/DarkGrey</material>
    <kp value="1000000.0"/>
    <kd value="100.0"/>
  </gazebo>
  <gazebo reference="L_LHipRx">
    <mu1>0.2</mu1>
    <mu2>0.2</mu2>
    <material>Gazebo/DarkGrey</material>
    <kp value="1000000.0"/>
    <kd value="100.0"/>
  </gazebo>
  <gazebo reference="L_LThigh">
    <mu1>0.2</mu1>
    <mu2>0.2</mu2>
    <material>Gazebo/DarkGrey</material>
    <kp value="1000000.0"/>
    <kd value="100.0"/>
  </gazebo>
  <gazebo reference="L_LShank">
    <mu1>0.2</mu1>
    <mu2>0.2</mu2>
    <material>Gazebo/DarkGrey</material>
    <kp value="1000000.0"/>
    <kd value="100.0"/>
  </gazebo>
  <gazebo reference="L_Foot">
    <mu1>0.2</mu1>
    <mu2>0.2</mu2>
    <material>Gazebo/DarkGrey</material>
    <kp value="1000000.0"/>
    <kd value="100.0"/>
  </gazebo>
  <transmission name="L_JHipRz_tran">
    <type>transmission_interface/SimpleTransmission</type>
    <joint name="L_JHipRz">
      <hardwareInterface>hardware_interface/EffortJointInterface</hardwareInterface>
    </joint>
    <actuator name="L_JHipRz_motor">
      <hardwareInterface>hardware_interface/EffortJointInterface</hardwareInterface>
      <mechanicalReduction>1</mechanicalReduction>
    </actuator>
  </transmission>
  <transmission name="L_JHipRx_tran">
    <type>transmission_interface/SimpleTransmission</type>
    <joint name="L_JHipRx">
      <hardwareInterface>hardware_interface/EffortJointInterface</hardwareInterface>
    </joint>
    <actuator name="L_JHipRx_motor">
      <hardwareInterface>hardware_interface/EffortJointInterface</hardwareInterface>
      <mechanicalReduction>1</mechanicalReduction>
    </actuator>
  </transmission>
  <transmission name="L_JThigh_tran">
    <type>transmission_interface/SimpleTransmission</type>
    <joint name="L_JThigh">
      <hardwareInterface>hardware_interface/EffortJointInterface</hardwareInterface>
    </joint>
    <actuator name="L_JThigh_motor">
      <hardwareInterface>hardware_interface/EffortJointInterface</hardwareInterface>
      <mechanicalReduction>1</mechanicalReduction>
    </actuator>
  </transmission>
  <transmission name="L_JKnee_tran">
    <type>transmission_interface/SimpleTransmission</type>
    <joint name="L_JKnee">
      <hardwareInterface>hardware_interface/EffortJointInterface</hardwareInterface>
    </joint>
    <actuator name="L_JKnee_motor">
      <hardwareInterface>hardware_interface/EffortJointInterface</hardwareInterface>
      <mechanicalReduction>1</mechanicalReduction>
    </actuator>
  </transmission>
  <transmission name="L_JAnkle_tran">
    <type>transmission_interface/SimpleTransmission</type>
    <joint name="L_JAnkle">
      <hardwareInterface>hardware_interface/EffortJointInterface</hardwareInterface>
    </joint>
    <actuator name="L_JAnkle_motor">
      <hardwareInterface>hardware_interface/EffortJointInterface</hardwareInterface>
      <mechanicalReduction>1</mechanicalReduction>
    </actuator>
  </transmission>
  <joint name="R_JHipRz" type="revolute">
    <origin rpy="0 0 0" xyz="0 -0.075 0"/>
    <parent link="base"/>
    <child link="R_LHipRz"/>
    <axis xyz="0 0 1"/>
    <dynamics damping="0" friction="0"/>
    <limit effort="33.5" lower="-0.8028514559173915" upper="0.8028514559173915" velocity="21"/>
  </joint>
  <link name="R_LHipRz">
    <visual>
      <origin rpy="0 0 0.0" xyz="0 0 0"/>
      <geometry>
        <mesh filename="package://legged_unitree_description/meshes/a1/R_HipRz.dae" scale="1 1 1"/>
      </geometry>
      <material name="orange"/>
    </visual>
    <inertial>
      <origin rpy="0 0 0" xyz="0.0 0.0 -0.01"/>
      <mass value="0.30"/>
      <inertia ixx="0.003735" ixy="0.0" ixz="0.0" iyy="0.01391" iyz="0.0" izz="0.01355"/>
    </inertial>
  </link>
  <joint name="R_JHipRx" type="revolute">
    <origin rpy="0 0 0" xyz="-0.041 0.0 -0.0885"/>
    <parent link="R_LHipRz"/>
    <child link="R_LHipRx"/>
    <axis xyz="1 0 0"/>
    <dynamics damping="0" friction="0"/>
    <limit effort="33.5" lower="-0.8028514559173915" upper="-0.8028514559173915" velocity="33.5"/>
  </joint>
  <link name="R_LHipRx">
    <visual>
      <origin rpy="0 -1.57 0.0" xyz="0 0 0"/>
      <geometry>
        <mesh filename="package://legged_unitree_description/meshes/a1/R_HipRx.dae" scale="1 1 1"/>
      </geometry>
      <material name="orange"/>
    </visual>
    <inertial>
      <origin rpy="0 0 0" xyz="0.0 0.0 -0.01"/>
      <mass value="0.30"/>
      <inertia ixx="0.003735" ixy="0.0" ixz="0.0" iyy="0.01391" iyz="0.0" izz="0.01355"/>
    </inertial>
  </link>
  <joint name="R_JThigh" type="revolute">
    <origin rpy="0 0 0" xyz="0.065 0.0 0.0"/>
    <parent link="R_LHipRx"/>
    <child link="R_LThigh"/>
    <axis xyz="0 1 0"/>
    <dynamics damping="0" friction="0"/>
    <limit effort="33.5" lower="-0.8028514559173915" upper="-0.8028514559173915" velocity="33.5"/>
  </joint>
  <link name="R_LThigh">
    <visual>
      <origin rpy="0 1.57 -1.57" xyz="0 0 0"/>
      <geometry>
        <mesh filename="package://legged_unitree_description/meshes/a1/R_Thigh.dae" scale="1 1 1"/>
      </geometry>
      <material name="orange"/>
    </visual>
    <inertial>
      <origin rpy="0 0 0" xyz="0.0 0.0 -0.01"/>
      <mass value="1.0"/>
      <inertia ixx="0.003735" ixy="0.0" ixz="0.0" iyy="0.01391" iyz="0.0" izz="0.01355"/>
    </inertial>
  </link>
  <joint name="R_JKnee" type="revolute">
    <origin rpy="0 0 0" xyz="0.0 0.017875 -0.247"/>
    <parent link="R_LThigh"/>
    <child link="R_LShank"/>
    <axis xyz="0 1 0"/>
    <dynamics damping="0" friction="0"/>
    <limit effort="33.5" lower="-0.8028514559173915" upper="-0.8028514559173915" velocity="33.5"/>
  </joint>
  <link name="R_LShank">
    <visual>
      <origin rpy="1.57 1.57 0" xyz="0 0 0"/>
      <geometry>
        <mesh filename="package://legged_unitree_description/meshes/a1/R_LowerLeg3_drawing.dae" scale="1 1 1"/>
      </geometry>
      <material name="orange"/>
    </visual>
    <inertial>
      <origin rpy="0 0 0" xyz="-0.03416 -0.00075 -0.01"/>
      <mass value="0.70"/>
      <inertia ixx="0.003735" ixy="0.0" ixz="0.0" iyy="0.01391" iyz="0.0" izz="0.01355"/>
    </inertial>
  </link>
  <joint name="R_JAnkle" type="revolute">
    <origin rpy="0 0 0" xyz="0.0 0.0 -0.247"/>
    <parent link="R_LShank"/>
    <child link="R_Foot"/>
    <axis xyz="0 1 0"/>
    <dynamics damping="0" friction="0"/>
    <limit effort="33.5" lower="-0.8028514559173915" upper="-0.8028514559173915" velocity="33.5"/>
  </joint>
  <link name="R_Foot">
    <visual>
      <origin rpy="1.57 1.57 0" xyz="0 0 0"/>
      <geometry>
        <mesh filename="package://legged_unitree_description/meshes/a1/R_foot_drawing.dae" scale="1 1 1"/>
      </geometry>
      <material name="orange"/>
    </visual>
    <visual>
      <geometry>
        <sphere radius="0.001"/>
      </geometry>
      <origin rpy="0 0 0" xyz="0.125 0.0 -0.033"/>
    </visual>
    <collision>
      <geometry>
        <sphere radius="0.0"/>
      </geometry>
      <origin rpy="0 0 0" xyz="0.125 0.0 -0.033"/>
    </collision>
    <visual>
      <geometry>
        <sphere radius="0.001"/>
      </geometry>
      <origin rpy="0 0 0" xyz="-0.025 0.0 -0.033"/>
    </visual>
    <collision>
      <geometry>
        <sphere radius="0.0"/>
      </geometry>
      <origin rpy="0 0 0" xyz="-0.025 0.0 -0.033"/>
    </collision>
    <inertial>
      <origin rpy="0 0 0" xyz="0.0 0.0 -0.01"/>
      <mass value="0.30"/>
      <inertia ixx="0.003735" ixy="0.0" ixz="0.0" iyy="0.01391" iyz="0.0" izz="0.01355"/>
    </inertial>
  </link>
  <gazebo reference="R_LHipRz">
    <mu1>0.2</mu1>
    <mu2>0.2</mu2>
    <material>Gazebo/DarkGrey</material>
    <kp value="1000000.0"/>
    <kd value="100.0"/>
  </gazebo>
  <gazebo reference="R_LHipRx">
    <mu1>0.2</mu1>
    <mu2>0.2</mu2>
    <material>Gazebo/DarkGrey</material>
    <kp value="1000000.0"/>
    <kd value="100.0"/>
  </gazebo>
  <gazebo reference="R_LThigh">
    <mu1>0.2</mu1>
    <mu2>0.2</mu2>
    <material>Gazebo/DarkGrey</material>
    <kp value="1000000.0"/>
    <kd value="100.0"/>
  </gazebo>
  <gazebo reference="R_LShank">
    <mu1>0.2</mu1>
    <mu2>0.2</mu2>
    <material>Gazebo/DarkGrey</material>
    <kp value="1000000.0"/>
    <kd value="100.0"/>
  </gazebo>
  <gazebo reference="R_Foot">
    <mu1>0.2</mu1>
    <mu2>0.2</mu2>
    <material>Gazebo/DarkGrey</material>
    <kp value="1000000.0"/>
    <kd value="100.0"/>
  </gazebo>
  <transmission name="R_JHipRz_tran">
    <type>transmission_interface/SimpleTransmission</type>
    <joint name="R_JHipRz">
      <hardwareInterface>hardware_interface/EffortJointInterface</hardwareInterface>
    </joint>
    <actuator name="R_JHipRz_motor">
      <hardwareInterface>hardware_interface/EffortJointInterface</hardwareInterface>
      <mechanicalReduction>1</mechanicalReduction>
    </actuator>
  </transmission>
  <transmission name="R_JHipRx_tran">
    <type>transmission_interface/SimpleTransmission</type>
    <joint name="R_JHipRx">
      <hardwareInterface>hardware_interface/EffortJointInterface</hardwareInterface>
    </joint>
    <actuator name="R_JHipRx_motor">
      <hardwareInterface>hardware_interface/EffortJointInterface</hardwareInterface>
      <mechanicalReduction>1</mechanicalReduction>
    </actuator>
  </transmission>
  <transmission name="R_JThigh_tran">
    <type>transmission_interface/SimpleTransmission</type>
    <joint name="R_JThigh">
      <hardwareInterface>hardware_interface/EffortJointInterface</hardwareInterface>
    </joint>
    <actuator name="R_JThigh_motor">
      <hardwareInterface>hardware_interface/EffortJointInterface</hardwareInterface>
      <mechanicalReduction>1</mechanicalReduction>
    </actuator>
  </transmission>
  <transmission name="R_JKnee_tran">
    <type>transmission_interface/SimpleTransmission</type>
    <joint name="R_JKnee">
      <hardwareInterface>hardware_interface/EffortJointInterface</hardwareInterface>
    </joint>
    <actuator name="R_JKnee_motor">
      <hardwareInterface>hardware_interface/EffortJointInterface</hardwareInterface>
      <mechanicalReduction>1</mechanicalReduction>
    </actuator>
  </transmission>
  <transmission name="R_JAnkle_tran">
    <type>transmission_interface/SimpleTransmission</type>
    <joint name="R_JAnkle">
      <hardwareInterface>hardware_interface/EffortJointInterface</hardwareInterface>
    </joint>
    <actuator name="R_JAnkle_motor">
      <hardwareInterface>hardware_interface/EffortJointInterface</hardwareInterface>
      <mechanicalReduction>1</mechanicalReduction>
    </actuator>
  </transmission>
  <joint name="L_JShoulderRx" type="revolute">
    <origin rpy="0 0 0" xyz="-0.0215 0.1115 0.202"/>
    <parent link="base"/>
    <child link="L_LShoulderRx"/>
    <axis xyz="1 0 0"/>
    <dynamics damping="0" friction="0"/>
    <limit effort="33.5" lower="-0.8028514559173915" upper="0.8028514559173915" velocity="21"/>
  </joint>
  <link name="L_LShoulderRx">
    <visual>
      <origin rpy="0 0 0.0" xyz="0.06 0.02 -0.055"/>
      <geometry>
        <mesh filename="package://legged_unitree_description/meshes/a1/L_ShoulderRx.dae" scale="1 1 1"/>
      </geometry>
      <material name="orange"/>
    </visual>
    <inertial>
      <origin rpy="0 0 0" xyz="0.01 0.0 0.0"/>
      <mass value="0.30"/>
      <inertia ixx="0.003735" ixy="0.0" ixz="0.0" iyy="0.01391" iyz="0.0" izz="0.01355"/>
    </inertial>
  </link>
  <joint name="L_JUpperArm" type="revolute">
    <origin rpy="0 0 0" xyz="0.0545 0.0 0.0"/>
    <parent link="L_LShoulderRx"/>
    <child link="L_LUpperArm"/>
    <axis xyz="0 1 0"/>
    <dynamics damping="0" friction="0"/>
    <limit effort="33.5" lower="-0.8028514559173915" upper="-0.8028514559173915" velocity="33.5"/>
  </joint>
  <link name="L_LUpperArm">
    <visual>
      <origin rpy="0 1.57 -1.57" xyz="0. 0.07 0"/>
      <geometry>
        <mesh filename="package://legged_unitree_description/meshes/a1/L_UpperArm.dae" scale="1 1 1"/>
      </geometry>
      <material name="orange"/>
    </visual>
    <inertial>
      <origin rpy="0 0 0" xyz="0.0 0.0 -0.09"/>
      <mass value="0.37"/>
      <inertia ixx="0.003735" ixy="0.0" ixz="0.0" iyy="0.01391" iyz="0.0" izz="0.01355"/>
    </inertial>
  </link>
  <joint name="L_JForeArm" type="revolute">
    <origin rpy="0 0 0" xyz="0.0 0.068 -0.195"/>
    <parent link="L_LUpperArm"/>
    <child link="L_LForeArm"/>
    <axis xyz="0 1 0"/>
    <dynamics damping="0" friction="0"/>
    <limit effort="33.5" lower="-0.8028514559173915" upper="-0.8028514559173915" velocity="33.5"/>
  </joint>
  <link name="L_LForeArm">
    <visual>
      <origin rpy="0 1.57 0" xyz="0. 0 0"/>
      <geometry>
        <mesh filename="package://legged_unitree_description/meshes/a1/L_ForeArm2.dae" scale="1 1 1"/>
      </geometry>
      <material name="orange"/>
    </visual>
    <inertial>
      <origin rpy="0 0 0" xyz="0.0 0.0 -0.04"/>
      <mass value="0.1"/>
      <inertia ixx="0.003735" ixy="0.0" ixz="0.0" iyy="0.01391" iyz="0.0" izz="0.01355"/>
    </inertial>
  </link>
  <gazebo reference="L_LShoulderRx">
    <mu1>0.2</mu1>
    <mu2>0.2</mu2>
    <material>Gazebo/DarkGrey</material>
    <kp value="1000000.0"/>
    <kd value="100.0"/>
  </gazebo>
  <gazebo reference="L_LShoulderRx">
    <mu1>0.2</mu1>
    <mu2>0.2</mu2>
    <material>Gazebo/DarkGrey</material>
    <kp value="1000000.0"/>
    <kd value="100.0"/>
  </gazebo>
  <gazebo reference="L_LUpperArm">
    <mu1>0.2</mu1>
    <mu2>0.2</mu2>
    <material>Gazebo/DarkGrey</material>
    <kp value="1000000.0"/>
    <kd value="100.0"/>
  </gazebo>
  <transmission name="L_JShoulderRx_tran">
    <type>transmission_interface/SimpleTransmission</type>
    <joint name="L_JShoulderRx">
      <hardwareInterface>hardware_interface/EffortJointInterface</hardwareInterface>
    </joint>
    <actuator name="L_JShoulderRx_motor">
      <hardwareInterface>hardware_interface/EffortJointInterface</hardwareInterface>
      <mechanicalReduction>1</mechanicalReduction>
    </actuator>
  </transmission>
  <transmission name="L_JUpperArm_tran">
    <type>transmission_interface/SimpleTransmission</type>
    <joint name="L_JUpperArm">
      <hardwareInterface>hardware_interface/EffortJointInterface</hardwareInterface>
    </joint>
    <actuator name="L_JUpperArm_motor">
      <hardwareInterface>hardware_interface/EffortJointInterface</hardwareInterface>
      <mechanicalReduction>1</mechanicalReduction>
    </actuator>
  </transmission>
  <transmission name="L_JForeArm_tran">
    <type>transmission_interface/SimpleTransmission</type>
    <joint name="L_JForeArm">
      <hardwareInterface>hardware_interface/EffortJointInterface</hardwareInterface>
    </joint>
    <actuator name="L_JForeArm_motor">
      <hardwareInterface>hardware_interface/EffortJointInterface</hardwareInterface>
      <mechanicalReduction>1</mechanicalReduction>
    </actuator>
  </transmission>
  <joint name="R_JShoulderRx" type="revolute">
    <origin rpy="0 0 0" xyz="-0.0215 -0.1115 0.202"/>
    <parent link="base"/>
    <child link="R_LShoulderRx"/>
    <axis xyz="1 0 0"/>
    <dynamics damping="0" friction="0"/>
    <limit effort="33.5" lower="-0.8028514559173915" upper="0.8028514559173915" velocity="21"/>
  </joint>
  <link name="R_LShoulderRx">
    <visual>
      <origin rpy="0 0 0.0" xyz="0.06 0.02 -0.055"/>
      <geometry>
        <mesh filename="package://legged_unitree_description/meshes/a1/R_ShoulderRx.dae" scale="1 1 1"/>
      </geometry>
      <material name="orange"/>
    </visual>
    <inertial>
      <origin rpy="0 0 0" xyz="0.01 0.0 0.0"/>
      <mass value="0.30"/>
      <inertia ixx="0.003735" ixy="0.0" ixz="0.0" iyy="0.01391" iyz="0.0" izz="0.01355"/>
    </inertial>
  </link>
  <joint name="R_JUpperArm" type="revolute">
    <origin rpy="0 0 0" xyz="0.0545 0.0 0.0"/>
    <parent link="R_LShoulderRx"/>
    <child link="R_LUpperArm"/>
    <axis xyz="0 1 0"/>
    <dynamics damping="0" friction="0"/>
    <limit effort="33.5" lower="-0.8028514559173915" upper="-0.8028514559173915" velocity="33.5"/>
  </joint>
  <link name="R_LUpperArm">
    <visual>
      <origin rpy="0 1.57 -1.57" xyz="0. -0.07 0"/>
      <geometry>
        <mesh filename="package://legged_unitree_description/meshes/a1/R_UpperArm.dae" scale="1 1 1"/>
      </geometry>
      <material name="orange"/>
    </visual>
    <inertial>
      <origin rpy="0 0 0" xyz="0.0 0.0 -0.09"/>
      <mass value="0.37"/>
      <inertia ixx="0.003735" ixy="0.0" ixz="0.0" iyy="0.01391" iyz="0.0" izz="0.01355"/>
    </inertial>
  </link>
  <joint name="R_JForeArm" type="revolute">
    <origin rpy="0 0 0" xyz="0.0 -0.068 -0.195"/>
    <parent link="R_LUpperArm"/>
    <child link="R_LForeArm"/>
    <axis xyz="0 1 0"/>
    <dynamics damping="0" friction="0"/>
    <limit effort="33.5" lower="-0.8028514559173915" upper="-0.8028514559173915" velocity="33.5"/>
  </joint>
  <link name="R_LForeArm">
    <visual>
      <origin rpy="0 1.57 0" xyz="0. 0 0"/>
      <geometry>
        <mesh filename="package://legged_unitree_description/meshes/a1/R_ForeArm2.dae" scale="1 1 1"/>
      </geometry>
      <material name="orange"/>
    </visual>
    <inertial>
      <origin rpy="0 0 0" xyz="0.0 0.0 -0.04"/>
      <mass value="0.1"/>
      <inertia ixx="0.003735" ixy="0.0" ixz="0.0" iyy="0.01391" iyz="0.0" izz="0.01355"/>
    </inertial>
  </link>
  <gazebo reference="R_LShoulderRx">
    <mu1>0.2</mu1>
    <mu2>0.2</mu2>
    <material>Gazebo/DarkGrey</material>
    <kp value="1000000.0"/>
    <kd value="100.0"/>
  </gazebo>
  <gazebo reference="R_LShoulderRx">
    <mu1>0.2</mu1>
    <mu2>0.2</mu2>
    <material>Gazebo/DarkGrey</material>
    <kp value="1000000.0"/>
    <kd value="100.0"/>
  </gazebo>
  <gazebo reference="R_LUpperArm">
    <mu1>0.2</mu1>
    <mu2>0.2</mu2>
    <material>Gazebo/DarkGrey</material>
    <kp value="1000000.0"/>
    <kd value="100.0"/>
  </gazebo>
  <transmission name="R_JShoulderRx_tran">
    <type>transmission_interface/SimpleTransmission</type>
    <joint name="R_JShoulderRx">
      <hardwareInterface>hardware_interface/EffortJointInterface</hardwareInterface>
    </joint>
    <actuator name="R_JShoulderRx_motor">
      <hardwareInterface>hardware_interface/EffortJointInterface</hardwareInterface>
      <mechanicalReduction>1</mechanicalReduction>
    </actuator>
  </transmission>
  <transmission name="R_JUpperArm_tran">
    <type>transmission_interface/SimpleTransmission</type>
    <joint name="R_JUpperArm">
      <hardwareInterface>hardware_interface/EffortJointInterface</hardwareInterface>
    </joint>
    <actuator name="R_JUpperArm_motor">
      <hardwareInterface>hardware_interface/EffortJointInterface</hardwareInterface>
      <mechanicalReduction>1</mechanicalReduction>
    </actuator>
  </transmission>
  <transmission name="R_JForeArm_tran">
    <type>transmission_interface/SimpleTransmission</type>
    <joint name="R_JForeArm">
      <hardwareInterface>hardware_interface/EffortJointInterface</hardwareInterface>
    </joint>
    <actuator name="R_JForeArm_motor">
      <hardwareInterface>hardware_interface/EffortJointInterface</hardwareInterface>
      <mechanicalReduction>1</mechanicalReduction>
    </actuator>
  </transmission>
</robot>
