<?xml version="1.0"?>

<robot xmlns:xacro="http://www.ros.org/wiki/xacro">

    <xacro:include filename="$(find legged_unitree_description)/urdf/common/transmission.xacro"/>

    <xacro:macro name="leg" params="prefix mirror mirror_dae front_hind front_hind_dae *origin">

        <joint name="${prefix}_JHipRz" type="revolute">
            <xacro:insert_block name="origin"/>
            <parent link="base"/>
            <child link="${prefix}_LHipRz"/>
            <axis xyz="0 0 1"/>
            <dynamics damping="${damping}" friction="${friction}"/>
            <limit effort="${hip_torque_max}" velocity="${hip_velocity_max}" lower="${hip_min}" upper="${hip_max}"/>
        </joint>

        <link name="${prefix}_LHipRz">
            <visual>
                <origin rpy="0 0 0.0" xyz="0 0 0"/>
                <geometry>
                    <mesh filename="package://legged_unitree_description/meshes/$(arg robot_type)/${prefix}_HipRz.obj"
                            scale="1 1 1"/>
                </geometry>
                <material name="orange"/>
            </visual>
            <inertial>
                <origin rpy="0 0 0" xyz="0.0 0.0 -0.01"/>
                <mass value="0.30"/>
                <inertia
                        ixx="0.003735" ixy="0.0" ixz="0.0"
                        iyy="0.01391" iyz="0.0"
                        izz="0.01355"/>
            </inertial>
        </link>

        <joint name="${prefix}_JHipRx" type="revolute">
            <origin rpy="0 0 0" xyz="-0.041 0.0 -0.0885"/>
            <parent link="${prefix}_LHipRz"/>
            <child link="${prefix}_LHipRx"/>
            <axis xyz="1 0 0"/>
            <dynamics damping="${damping}" friction="${friction}"/>
            <limit effort="${hip_torque_max}" velocity="${hip_torque_max}" lower="${hip_min}"
                   upper="${hip_max}"/>
        </joint>

        <link name="${prefix}_LHipRx">
            <visual>
                <xacro:if value="${(mirror == True)}">
                    <origin rpy="0 -3.14 -3.14" xyz="0. 0.00 -0.0"/>
                </xacro:if>
                <xacro:if value="${(mirror == False)}">
                    <origin rpy="0 0 0.0" xyz="0 0 0.0"/>
                </xacro:if>
                <geometry>
                    <mesh filename="package://legged_unitree_description/meshes/$(arg robot_type)/${prefix}_HipRx.obj"
                            scale="1 1 1"/>
                </geometry>
                <material name="orange"/>
            </visual>
            <inertial>
                <origin rpy="0 0 0" xyz="0.0 0.0 -0.01"/>
                <mass value="0.30"/>
                <inertia
                        ixx="0.003735" ixy="0.0" ixz="0.0"
                        iyy="0.01391" iyz="0.0"
                        izz="0.01355"/>
            </inertial>
        </link>

        <joint name="${prefix}_JThigh" type="revolute">
            <origin rpy="0 0 0" xyz="0.065 0.0 0.0"/>
            <parent link="${prefix}_LHipRx"/>
            <child link="${prefix}_LThigh"/>
            <axis xyz="0 1 0"/>
            <dynamics damping="${damping}" friction="${friction}"/>
            <limit effort="${hip_torque_max}" velocity="${hip_torque_max}" lower="${hip_min}"
                   upper="${hip_max}"/>
        </joint>

        <link name="${prefix}_LThigh">
            <visual>
                <xacro:if value="${(mirror == True)}">
                    <origin rpy="0 0 -3.14" xyz="0. 0.00 -0.0"/>
                </xacro:if>
                <xacro:if value="${(mirror == False)}">
                    <origin rpy="0 0 0.0" xyz="0 0 0.0"/>
                </xacro:if>
                <geometry>
                    <mesh filename="package://legged_unitree_description/meshes/$(arg robot_type)/${prefix}_Thigh.obj"
                            scale="1 1 1"/>
                </geometry>
                <material name="orange"/>
            </visual>
            <inertial>
                <origin rpy="0 0 0" xyz="0.0 0.0 -0.01"/>
                <mass value="1.0"/>
                <inertia
                        ixx="0.003735" ixy="0.0" ixz="0.0"
                        iyy="0.01391" iyz="0.0"
                        izz="0.01355"/>
            </inertial>
        </link>

        <joint name="${prefix}_JKnee" type="revolute">
            <origin rpy="0 0 0" xyz="0.0 ${-0.017875*mirror} -0.247"/>
            <parent link="${prefix}_LThigh"/>
            <child link="${prefix}_LShank"/>
            <axis xyz="0 1 0"/>
            <dynamics damping="${damping}" friction="${friction}"/>
            <limit effort="${hip_torque_max}" velocity="${hip_torque_max}" lower="${hip_min}"
                   upper="${hip_max}"/>
        </joint>

        <link name="${prefix}_LShank">
            <visual>
                <origin rpy="0 -3.14 0" xyz="0 -0.6 0"/>
                <geometry>
                    <mesh filename="package://legged_unitree_description/meshes/$(arg robot_type)/${prefix}_LowerLeg3_drawing.obj"
                            scale="1 1 1"/>
                </geometry>
                <material name="orange"/>
            </visual>
            <inertial>
                <origin rpy="0 0 0" xyz="-0.03416 -0.00075 -0.01"/>
                <mass value="0.70"/>
                <inertia
                        ixx="0.003735" ixy="0.0" ixz="0.0"
                        iyy="0.01391" iyz="0.0"
                        izz="0.01355"/>
            </inertial>
        </link>

        <joint name="${prefix}_JAnkle" type="revolute">
            <origin rpy="0 0 0" xyz="0.0 0.0 -0.247"/>
            <parent link="${prefix}_LShank"/>
            <child link="${prefix}_Foot"/>
            <axis xyz="0 1 0"/>
            <dynamics damping="${damping}" friction="${friction}"/>
            <limit effort="${hip_torque_max}" velocity="${hip_torque_max}" lower="${hip_min}"
                   upper="${hip_max}"/>
        </joint>

        <link name="${prefix}_Foot">
            <visual>
                <origin rpy="1.57 1.57 0" xyz="0 0 0"/>
                <geometry>
                    <mesh filename="package://legged_unitree_description/meshes/$(arg robot_type)/${prefix}_foot_drawing.obj"
                            scale="1 1 1"/>
                </geometry>
                <material name="orange"/>
            </visual>
            <visual>
                <geometry>
                    <sphere radius="0.001"/>
                </geometry>
                <origin xyz="0.125 0.0 -0.033" rpy="0 0 0"/>
            </visual>
            <collision>
                <geometry>
                    <sphere radius="0.0"/>
                </geometry>
                <origin xyz="0.125 0.0 -0.033" rpy="0 0 0"/>
            </collision>

            <visual>
                <geometry>
                    <sphere radius="0.001"/>
                </geometry>
                <origin xyz="-0.025 0.0 -0.033" rpy="0 0 0"/>
            </visual>
            <collision>
                <geometry>
                    <sphere radius="0.0"/>
                </geometry>
                <origin xyz="-0.025 0.0 -0.033" rpy="0 0 0"/>
            </collision>

            <inertial>
                <origin rpy="0 0 0" xyz="0.0 0.0 -0.01"/>
                <mass value="0.30"/>
                <inertia
                        ixx="0.003735" ixy="0.0" ixz="0.0"
                        iyy="0.01391" iyz="0.0"
                        izz="0.01355"/>
            </inertial>
        </link>

        <gazebo reference="${prefix}_LHipRz">
            <mu1>0.2</mu1>
            <mu2>0.2</mu2>
            <material>Gazebo/DarkGrey</material>
            <kp value="1000000.0"/>
            <kd value="100.0"/>
        </gazebo>
        <gazebo reference="${prefix}_LHipRx">
            <mu1>0.2</mu1>
            <mu2>0.2</mu2>
            <material>Gazebo/DarkGrey</material>
            <kp value="1000000.0"/>
            <kd value="100.0"/>
        </gazebo>
        <gazebo reference="${prefix}_LThigh">
            <mu1>0.2</mu1>
            <mu2>0.2</mu2>
            <material>Gazebo/DarkGrey</material>
            <kp value="1000000.0"/>
            <kd value="100.0"/>
        </gazebo>
        <gazebo reference="${prefix}_LShank">
            <mu1>0.2</mu1>
            <mu2>0.2</mu2>
            <material>Gazebo/DarkGrey</material>
            <kp value="1000000.0"/>
            <kd value="100.0"/>
        </gazebo>
        <gazebo reference="${prefix}_Foot">
            <mu1>0.2</mu1>
            <mu2>0.2</mu2>
            <material>Gazebo/DarkGrey</material>
            <kp value="1000000.0"/>
            <kd value="100.0"/>
        </gazebo>
        <xacro:leg_transmission name="${prefix}"/>
    </xacro:macro>
</robot>
